Workbook

Sheet Sheet1
A1: Wave (nm) | B1: No Mask | C1: Mask | E1: Wave (nm) | F1: Mask | G1: No Mask | I1: Wave (nm) | J1: Mask | K1: No Mask
A2: 250 | B2: 4.09e-12 | C2: 5.871e-11 | E2: 338.95 | F2: 0 | G2: 0 | I2: 340 | J2: =FORECAST($I2, INDEX(F$2:F$2049,MATCH($I2,$E$2:$E$2049,1)):INDEX(F$2:F$2049,MATCH($I2,$E$2:$E$2049,1)+1), INDEX($E$2:$E2049,MATCH($I2,$E$2:$E$2049,1)):INDEX($E$2:$E$2049,MATCH($I2,$E$2:$E$2049,1)+1)) -> 40.952953 | K2: =FORECAST($I2, INDEX(G$2:G$2049,MATCH($I2,$E$2:$E$2049,1)):INDEX(G$2:G$2049,MATCH($I2,$E$2:$E$2049,1)+1), INDEX($E$2:$E2049,MATCH($I2,$E$2:$E$2049,1)):INDEX($E$2:$E$2049,MATCH($I2,$E$2:$E$2049,1)+1)) -> 135.74947
A3: 260 | B3: 3.947e-12 | C3: 8.796e-11 | E3: 339.32 | F3: 40.4774 | G3: 133.85 | I3: 341 | J3: =FORECAST($I3, INDEX(F$2:F$2049,MATCH($I3,$E$2:$E$2049,1)):INDEX(F$2:F$2049,MATCH($I3,$E$2:$E$2049,1)+1), INDEX($E$2:$E2050,MATCH($I3,$E$2:$E$2049,1)):INDEX($E$2:$E$2049,MATCH($I3,$E$2:$E$2049,1)+1)) -> 41.853665 | K3: =FORECAST($I3, INDEX(G$2:G$2049,MATCH($I3,$E$2:$E$2049,1)):INDEX(G$2:G$2049,MATCH($I3,$E$2:$E$2049,1)+1), INDEX($E$2:$E2050,MATCH($I3,$E$2:$E$2049,1)):INDEX($E$2:$E$2049,MATCH($I3,$E$2:$E$2049,1)+1)) -> 137.93216
A4: 270 | B4: 4.29e-12 | C4: 1.293e-10 | E4: 339.7 | F4: 40.8129 | G4: 134.51 | I4: 342 | J4: =FORECAST($I4, INDEX(F$2:F$2049,MATCH($I4,$E$2:$E$2049,1)):INDEX(F$2:F$2049,MATCH($I4,$E$2:$E$2049,1)+1), INDEX($E$2:$E2051,MATCH($I4,$E$2:$E$2049,1)):INDEX($E$2:$E$2049,MATCH($I4,$E$2:$E$2049,1)+1)) -> 42.278914 | K4: =FORECAST($I4, INDEX(G$2:G$2049,MATCH($I4,$E$2:$E$2049,1)):INDEX(G$2:G$2049,MATCH($I4,$E$2:$E$2049,1)+1), INDEX($E$2:$E2051,MATCH($I4,$E$2:$E$2049,1)):INDEX($E$2:$E$2049,MATCH($I4,$E$2:$E$2049,1)+1)) -> 139.40568
A5: 280 | B5: 3.953e-12 | C5: 1.838e-10 | E5: 340.08 | F5: 40.9903 | G5: 136.08 | I5: 343 | J5: =FORECAST($I5, INDEX(F$2:F$2049,MATCH($I5,$E$2:$E$2049,1)):INDEX(F$2:F$2049,MATCH($I5,$E$2:$E$2049,1)+1), INDEX($E$2:$E2052,MATCH($I5,$E$2:$E$2049,1)):INDEX($E$2:$E$2049,MATCH($I5,$E$2:$E$2049,1)+1)) -> 42.592146 | K5: =FORECAST($I5, INDEX(G$2:G$2049,MATCH($I5,$E$2:$E$2049,1)):INDEX(G$2:G$2049,MATCH($I5,$E$2:$E$2049,1)+1), INDEX($E$2:$E2052,MATCH($I5,$E$2:$E$2049,1)):INDEX($E$2:$E$2049,MATCH($I5,$E$2:$E$2049,1)+1)) -> 139.92486
A6: 290 | B6: 3.901e-12 | C6: 2.682e-10 | E6: 340.45 | F6: 41.4129 | G6: 136.69 | I6: 344 | J6: =FORECAST($I6, INDEX(F$2:F$2049,MATCH($I6,$E$2:$E$2049,1)):INDEX(F$2:F$2049,MATCH($I6,$E$2:$E$2049,1)+1), INDEX($E$2:$E2053,MATCH($I6,$E$2:$E$2049,1)):INDEX($E$2:$E$2049,MATCH($I6,$E$2:$E$2049,1)+1)) -> 42.662342 | K6: =FORECAST($I6, INDEX(G$2:G$2049,MATCH($I6,$E$2:$E$2049,1)):INDEX(G$2:G$2049,MATCH($I6,$E$2:$E$2049,1)+1), INDEX($E$2:$E2053,MATCH($I6,$E$2:$E$2049,1)):INDEX($E$2:$E$2049,MATCH($I6,$E$2:$E$2049,1)+1)) -> 140.31842
A7: 300 | B7: 3.614e-12 | C7: 3.669e-10 | E7: 340.83 | F7: 41.7677 | G7: 137.73 | I7: 345 | J7: =FORECAST($I7, INDEX(F$2:F$2049,MATCH($I7,$E$2:$E$2049,1)):INDEX(F$2:F$2049,MATCH($I7,$E$2:$E$2049,1)+1), INDEX($E$2:$E2054,MATCH($I7,$E$2:$E$2049,1)):INDEX($E$2:$E$2049,MATCH($I7,$E$2:$E$2049,1)+1)) -> 42.529824 | K7: =FORECAST($I7, INDEX(G$2:G$2049,MATCH($I7,$E$2:$E$2049,1)):INDEX(G$2:G$2049,MATCH($I7,$E$2:$E$2049,1)+1), INDEX($E$2:$E2054,MATCH($I7,$E$2:$E$2049,1)):INDEX($E$2:$E$2049,MATCH($I7,$E$2:$E$2049,1)+1)) -> 140.17378
A8: 310 | B8: 4.039e-12 | C8: 4.938e-10 | E8: 341.2 | F8: 41.9548 | G8: 138.17 | I8: 346 | J8: =FORECAST($I8, INDEX(F$2:F$2049,MATCH($I8,$E$2:$E$2049,1)):INDEX(F$2:F$2049,MATCH($I8,$E$2:$E$2049,1)+1), INDEX($E$2:$E2055,MATCH($I8,$E$2:$E$2049,1)):INDEX($E$2:$E$2049,MATCH($I8,$E$2:$E$2049,1)+1)) -> 42.438986 | K8: =FORECAST($I8, INDEX(G$2:G$2049,MATCH($I8,$E$2:$E$2049,1)):INDEX(G$2:G$2049,MATCH($I8,$E$2:$E$2049,1)+1), INDEX($E$2:$E2055,MATCH($I8,$E$2:$E$2049,1)):INDEX($E$2:$E$2049,MATCH($I8,$E$2:$E$2049,1)+1)) -> 140.48378
A9: 320 | B9: 4.205e-12 | C9: 6.296e-10 | E9: 341.58 | F9: 42.2097 | G9: 138.97 | I9: 347 | J9: =FORECAST($I9, INDEX(F$2:F$2049,MATCH($I9,$E$2:$E$2049,1)):INDEX(F$2:F$2049,MATCH($I9,$E$2:$E$2049,1)+1), INDEX($E$2:$E2056,MATCH($I9,$E$2:$E$2049,1)):INDEX($E$2:$E$2049,MATCH($I9,$E$2:$E$2049,1)+1)) -> 42.503732 | K9: =FORECAST($I9, INDEX(G$2:G$2049,MATCH($I9,$E$2:$E$2049,1)):INDEX(G$2:G$2049,MATCH($I9,$E$2:$E$2049,1)+1), INDEX($E$2:$E2056,MATCH($I9,$E$2:$E$2049,1)):INDEX($E$2:$E$2049,MATCH($I9,$E$2:$E$2049,1)+1)) -> 139.94421
A10: 330 | B10: 4.545e-12 | C10: 7.772e-10 | E10: 341.95 | F10: 42.2484 | G10: 139.33 | I10: 348 | J10: =FORECAST($I10, INDEX(F$2:F$2049,MATCH($I10,$E$2:$E$2049,1)):INDEX(F$2:F$2049,MATCH($I10,$E$2:$E$2049,1)+1), INDEX($E$2:$E2057,MATCH($I10,$E$2:$E$2049,1)):INDEX($E$2:$E$2049,MATCH($I10,$E$2:$E$2049,1)+1)) -> 42.971805 | K10: =FORECAST($I10, INDEX(G$2:G$2049,MATCH($I10,$E$2:$E$2049,1)):INDEX(G$2:G$2049,MATCH($I10,$E$2:$E$2049,1)+1), INDEX($E$2:$E2057,MATCH($I10,$E$2:$E$2049,1)):INDEX($E$2:$E$2049,MATCH($I10,$E$2:$E$2049,1)+1)) -> 141.48324
A11: 340 | B11: 5.265e-12 | C11: 9.152e-10 | E11: 342.32 | F11: 42.4742 | G11: 139.89 | I11: 349 | J11: =FORECAST($I11, INDEX(F$2:F$2049,MATCH($I11,$E$2:$E$2049,1)):INDEX(F$2:F$2049,MATCH($I11,$E$2:$E$2049,1)+1), INDEX($E$2:$E2058,MATCH($I11,$E$2:$E$2049,1)):INDEX($E$2:$E$2049,MATCH($I11,$E$2:$E$2049,1)+1)) -> 43.975737 | K11: =FORECAST($I11, INDEX(G$2:G$2049,MATCH($I11,$E$2:$E$2049,1)):INDEX(G$2:G$2049,MATCH($I11,$E$2:$E$2049,1)+1), INDEX($E$2:$E2058,MATCH($I11,$E$2:$E$2049,1)):INDEX($E$2:$E$2049,MATCH($I11,$E$2:$E$2049,1)+1)) -> 143.91974
A12: 350 | B12: 4.999e-11 | C12: 9.71e-10 | E12: 342.7 | F12: 42.5032 | G12: 140.16 | I12: 350 | J12: =FORECAST($I12, INDEX(F$2:F$2049,MATCH($I12,$E$2:$E$2049,1)):INDEX(F$2:F$2049,MATCH($I12,$E$2:$E$2049,1)+1), INDEX($E$2:$E2059,MATCH($I12,$E$2:$E$2049,1)):INDEX($E$2:$E$2049,MATCH($I12,$E$2:$E$2049,1)+1)) -> 44.1935 | K12: =FORECAST($I12, INDEX(G$2:G$2049,MATCH($I12,$E$2:$E$2049,1)):INDEX(G$2:G$2049,MATCH($I12,$E$2:$E$2049,1)+1), INDEX($E$2:$E2059,MATCH($I12,$E$2:$E$2049,1)):INDEX($E$2:$E$2049,MATCH($I12,$E$2:$E$2049,1)+1)) -> 144.41757
A13: 360 | B13: 1.79e-10 | C13: 1.124e-09 | E13: 343.07 | F13: 42.6129 | G13: 139.87 | I13: 351 | J13: =FORECAST($I13, INDEX(F$2:F$2049,MATCH($I13,$E$2:$E$2049,1)):INDEX(F$2:F$2049,MATCH($I13,$E$2:$E$2049,1)+1), INDEX($E$2:$E2060,MATCH($I13,$E$2:$E$2049,1)):INDEX($E$2:$E$2049,MATCH($I13,$E$2:$E$2049,1)+1)) -> 44.028319 | K13: =FORECAST($I13, INDEX(G$2:G$2049,MATCH($I13,$E$2:$E$2049,1)):INDEX(G$2:G$2049,MATCH($I13,$E$2:$E$2049,1)+1), INDEX($E$2:$E2060,MATCH($I13,$E$2:$E$2049,1)):INDEX($E$2:$E$2049,MATCH($I13,$E$2:$E$2049,1)+1)) -> 144.66541
... A87: 1100 | B87: 6.086e-11 | C87: 2.154e-10 | E87: 370.73 | F87: 46.9161 | G87: 151.74 | I87: 425 | J87: =FORECAST($I87, INDEX(F$2:F$2049,MATCH($I87,$E$2:$E$2049,1)):INDEX(F$2:F$2049,MATCH($I87,$E$2:$E$2049,1)+1), INDEX($E$2:$E2134,MATCH($I87,$E$2:$E$2049,1)):INDEX($E$2:$E$2049,MATCH($I87,$E$2:$E$2049,1)+1)) -> 105.78351 | K87: =FORECAST($I87, INDEX(G$2:G$2049,MATCH($I87,$E$2:$E$2049,1)):INDEX(G$2:G$2049,MATCH($I87,$E$2:$E$2049,1)+1), INDEX($E$2:$E2134,MATCH($I87,$E$2:$E$2049,1)):INDEX($E$2:$E$2049,MATCH($I87,$E$2:$E$2049,1)+1)) -> 291.38459
E88: 371.11 | F88: 47.5419 | G88: 152.76 | I88: 426 | J88: =FORECAST($I88, INDEX(F$2:F$2049,MATCH($I88,$E$2:$E$2049,1)):INDEX(F$2:F$2049,MATCH($I88,$E$2:$E$2049,1)+1), INDEX($E$2:$E2135,MATCH($I88,$E$2:$E$2049,1)):INDEX($E$2:$E$2049,MATCH($I88,$E$2:$E$2049,1)+1)) -> 135.04108 | K88: =FORECAST($I88, INDEX(G$2:G$2049,MATCH($I88,$E$2:$E$2049,1)):INDEX(G$2:G$2049,MATCH($I88,$E$2:$E$2049,1)+1), INDEX($E$2:$E2135,MATCH($I88,$E$2:$E$2049,1)):INDEX($E$2:$E$2049,MATCH($I88,$E$2:$E$2049,1)+1)) -> 309.47108
E89: 371.48 | F89: 47.9129 | G89: 152.69 | I89: 427 | J89: =FORECAST($I89, INDEX(F$2:F$2049,MATCH($I89,$E$2:$E$2049,1)):INDEX(F$2:F$2049,MATCH($I89,$E$2:$E$2049,1)+1), INDEX($E$2:$E2136,MATCH($I89,$E$2:$E$2049,1)):INDEX($E$2:$E$2049,MATCH($I89,$E$2:$E$2049,1)+1)) -> 166.42281 | K89: =FORECAST($I89, INDEX(G$2:G$2049,MATCH($I89,$E$2:$E$2049,1)):INDEX(G$2:G$2049,MATCH($I89,$E$2:$E$2049,1)+1), INDEX($E$2:$E2136,MATCH($I89,$E$2:$E$2049,1)):INDEX($E$2:$E$2049,MATCH($I89,$E$2:$E$2049,1)+1)) -> 317.73946
E90: 371.85 | F90: 48.4129 | G90: 152.95 | I90: 428 | J90: =FORECAST($I90, INDEX(F$2:F$2049,MATCH($I90,$E$2:$E$2049,1)):INDEX(F$2:F$2049,MATCH($I90,$E$2:$E$2049,1)+1), INDEX($E$2:$E2137,MATCH($I90,$E$2:$E$2049,1)):INDEX($E$2:$E$2049,MATCH($I90,$E$2:$E$2049,1)+1)) -> 193.48933 | K90: =FORECAST($I90, INDEX(G$2:G$2049,MATCH($I90,$E$2:$E$2049,1)):INDEX(G$2:G$2049,MATCH($I90,$E$2:$E$2049,1)+1), INDEX($E$2:$E2137,MATCH($I90,$E$2:$E$2049,1)):INDEX($E$2:$E$2049,MATCH($I90,$E$2:$E$2049,1)+1)) -> 321.08333
E91: 372.22 | F91: 48.8194 | G91: 152.98 | I91: 429 | J91: =FORECAST($I91, INDEX(F$2:F$2049,MATCH($I91,$E$2:$E$2049,1)):INDEX(F$2:F$2049,MATCH($I91,$E$2:$E$2049,1)+1), INDEX($E$2:$E2138,MATCH($I91,$E$2:$E$2049,1)):INDEX($E$2:$E$2049,MATCH($I91,$E$2:$E$2049,1)+1)) -> 212.97835 | K91: =FORECAST($I91, INDEX(G$2:G$2049,MATCH($I91,$E$2:$E$2049,1)):INDEX(G$2:G$2049,MATCH($I91,$E$2:$E$2049,1)+1), INDEX($E$2:$E2138,MATCH($I91,$E$2:$E$2049,1)):INDEX($E$2:$E$2049,MATCH($I91,$E$2:$E$2049,1)+1)) -> 326.47892
E92: 372.6 | F92: 49.4258 | G92: 153.62 | I92: 430 | J92: =FORECAST($I92, INDEX(F$2:F$2049,MATCH($I92,$E$2:$E$2049,1)):INDEX(F$2:F$2049,MATCH($I92,$E$2:$E$2049,1)+1), INDEX($E$2:$E2139,MATCH($I92,$E$2:$E$2049,1)):INDEX($E$2:$E$2049,MATCH($I92,$E$2:$E$2049,1)+1)) -> 214.65965 | K92: =FORECAST($I92, INDEX(G$2:G$2049,MATCH($I92,$E$2:$E$2049,1)):INDEX(G$2:G$2049,MATCH($I92,$E$2:$E$2049,1)+1), INDEX($E$2:$E2139,MATCH($I92,$E$2:$E$2049,1)):INDEX($E$2:$E$2049,MATCH($I92,$E$2:$E$2049,1)+1)) -> 332.90378
E93: 372.97 | F93: 49.9226 | G93: 153.42 | I93: 431 | J93: =FORECAST($I93, INDEX(F$2:F$2049,MATCH($I93,$E$2:$E$2049,1)):INDEX(F$2:F$2049,MATCH($I93,$E$2:$E$2049,1)+1), INDEX($E$2:$E2140,MATCH($I93,$E$2:$E$2049,1)):INDEX($E$2:$E$2049,MATCH($I93,$E$2:$E$2049,1)+1)) -> 200.68546 | K93: =FORECAST($I93, INDEX(G$2:G$2049,MATCH($I93,$E$2:$E$2049,1)):INDEX(G$2:G$2049,MATCH($I93,$E$2:$E$2049,1)+1), INDEX($E$2:$E2140,MATCH($I93,$E$2:$E$2049,1)):INDEX($E$2:$E$2049,MATCH($I93,$E$2:$E$2049,1)+1)) -> 342.00649
E94: 373.34 | F94: 50.3194 | G94: 154.02 | I94: 432 | J94: =FORECAST($I94, INDEX(F$2:F$2049,MATCH($I94,$E$2:$E$2049,1)):INDEX(F$2:F$2049,MATCH($I94,$E$2:$E$2049,1)+1), INDEX($E$2:$E2141,MATCH($I94,$E$2:$E$2049,1)):INDEX($E$2:$E$2049,MATCH($I94,$E$2:$E$2049,1)+1)) -> 176.68808 | K94: =FORECAST($I94, INDEX(G$2:G$2049,MATCH($I94,$E$2:$E$2049,1)):INDEX(G$2:G$2049,MATCH($I94,$E$2:$E$2049,1)+1), INDEX($E$2:$E2141,MATCH($I94,$E$2:$E$2049,1)):INDEX($E$2:$E$2049,MATCH($I94,$E$2:$E$2049,1)+1)) -> 350.87973
E95: 373.71 | F95: 51.0774 | G95: 154.64 | I95: 433 | J95: =FORECAST($I95, INDEX(F$2:F$2049,MATCH($I95,$E$2:$E$2049,1)):INDEX(F$2:F$2049,MATCH($I95,$E$2:$E$2049,1)+1), INDEX($E$2:$E2142,MATCH($I95,$E$2:$E$2049,1)):INDEX($E$2:$E$2049,MATCH($I95,$E$2:$E$2049,1)+1)) -> 157.04635 | K95: =FORECAST($I95, INDEX(G$2:G$2049,MATCH($I95,$E$2:$E$2049,1)):INDEX(G$2:G$2049,MATCH($I95,$E$2:$E$2049,1)+1), INDEX($E$2:$E2142,MATCH($I95,$E$2:$E$2049,1)):INDEX($E$2:$E$2049,MATCH($I95,$E$2:$E$2049,1)+1)) -> 359.99541
E96: 374.09 | F96: 51.7 | G96: 154.51 | I96: 434 | J96: =FORECAST($I96, INDEX(F$2:F$2049,MATCH($I96,$E$2:$E$2049,1)):INDEX(F$2:F$2049,MATCH($I96,$E$2:$E$2049,1)+1), INDEX($E$2:$E2143,MATCH($I96,$E$2:$E$2049,1)):INDEX($E$2:$E$2049,MATCH($I96,$E$2:$E$2049,1)+1)) -> 145.40116 | K96: =FORECAST($I96, INDEX(G$2:G$2049,MATCH($I96,$E$2:$E$2049,1)):INDEX(G$2:G$2049,MATCH($I96,$E$2:$E$2049,1)+1), INDEX($E$2:$E2143,MATCH($I96,$E$2:$E$2049,1)):INDEX($E$2:$E$2049,MATCH($I96,$E$2:$E$2049,1)+1)) -> 368.66541
E97: 374.46 | F97: 52.2226 | G97: 155.24 | I97: 435 | J97: =FORECAST($I97, INDEX(F$2:F$2049,MATCH($I97,$E$2:$E$2049,1)):INDEX(F$2:F$2049,MATCH($I97,$E$2:$E$2049,1)+1), INDEX($E$2:$E2144,MATCH($I97,$E$2:$E$2049,1)):INDEX($E$2:$E$2049,MATCH($I97,$E$2:$E$2049,1)+1)) -> 141.54924 | K97: =FORECAST($I97, INDEX(G$2:G$2049,MATCH($I97,$E$2:$E$2049,1)):INDEX(G$2:G$2049,MATCH($I97,$E$2:$E$2049,1)+1), INDEX($E$2:$E2144,MATCH($I97,$E$2:$E$2049,1)):INDEX($E$2:$E$2049,MATCH($I97,$E$2:$E$2049,1)+1)) -> 379.65216
E98: 374.83 | F98: 52.6935 | G98: 155.18 | I98: 436 | J98: =FORECAST($I98, INDEX(F$2:F$2049,MATCH($I98,$E$2:$E$2049,1)):INDEX(F$2:F$2049,MATCH($I98,$E$2:$E$2049,1)+1), INDEX($E$2:$E2145,MATCH($I98,$E$2:$E$2049,1)):INDEX($E$2:$E$2049,MATCH($I98,$E$2:$E$2049,1)+1)) -> 143.492 | K98: =FORECAST($I98, INDEX(G$2:G$2049,MATCH($I98,$E$2:$E$2049,1)):INDEX(G$2:G$2049,MATCH($I98,$E$2:$E$2049,1)+1), INDEX($E$2:$E2145,MATCH($I98,$E$2:$E$2049,1)):INDEX($E$2:$E$2049,MATCH($I98,$E$2:$E$2049,1)+1)) -> 392.52703
E99: 375.2 | F99: 53.0581 | G99: 155.57 | I99: 437 | J99: =FORECAST($I99, INDEX(F$2:F$2049,MATCH($I99,$E$2:$E$2049,1)):INDEX(F$2:F$2049,MATCH($I99,$E$2:$E$2049,1)+1), INDEX($E$2:$E2146,MATCH($I99,$E$2:$E$2049,1)):INDEX($E$2:$E$2049,MATCH($I99,$E$2:$E$2049,1)+1)) -> 148.54516 | K99: =FORECAST($I99, INDEX(G$2:G$2049,MATCH($I99,$E$2:$E$2049,1)):INDEX(G$2:G$2049,MATCH($I99,$E$2:$E$2049,1)+1), INDEX($E$2:$E2146,MATCH($I99,$E$2:$E$2049,1)):INDEX($E$2:$E$2049,MATCH($I99,$E$2:$E$2049,1)+1)) -> 400.53
... E681: 586.11 | F681: 1271.12 | G681: 3623.92 | I681: 1019 | J681: =FORECAST($I681, INDEX(F$2:F$2049,MATCH($I681,$E$2:$E$2049,1)):INDEX(F$2:F$2049,MATCH($I681,$E$2:$E$2049,1)+1), INDEX($E$2:$E2728,MATCH($I681,$E$2:$E$2049,1)):INDEX($E$2:$E$2049,MATCH($I681,$E$2:$E$2049,1)+1)) -> 45.814452 | K681: =FORECAST($I681, INDEX(G$2:G$2049,MATCH($I681,$E$2:$E$2049,1)):INDEX(G$2:G$2049,MATCH($I681,$E$2:$E$2049,1)+1), INDEX($E$2:$E2728,MATCH($I681,$E$2:$E$2049,1)):INDEX($E$2:$E$2049,MATCH($I681,$E$2:$E$2049,1)+1)) -> 148.53667
E682: 586.46 | F682: 1288.01 | G682: 3633.72
E683: 586.82 | F683: 1306.3 | G683: 3636.4
E684: 587.17 | F684: 1322.88 | G684: 3639.72
E685: 587.52 | F685: 1337.28 | G685: 3627.95
E686: 587.87 | F686: 1353.46 | G686: 3623.49
E687: 588.22 | F687: 1378.79 | G687: 3627.18
E688: 588.57 | F688: 1405.52 | G688: 3639.92
E689: 588.92 | F689: 1433.91 | G689: 3645.89
E690: 589.27 | F690: 1461.16 | G690: 3644.28
E691: 589.62 | F691: 1487.62 | G691: 3642.11
E692: 589.98 | F692: 1519.43 | G692: 3649.22
E693: 590.33 | F693: 1548.1 | G693: 3641.09
... E2049: 1019.14 | F2049: 45.771 | G2049: 148.35

Sheet Sheet2
A1: Wave (nm) | B1: Wave New | C1: Throughput | D1: Corrected | E1: wshift | G1: Wave (nm) | H1: Throughput | J1: Wave (nm) | K1: Final
A2: 250 | B2: =A2+$E$2 -> 244 | C2: =Sheet1!B2/Sheet1!C2 -> 0.069664452 | D2: =C2*1.1 -> 0.076630898 | E2: -6 | G2: 340 | H2: =Sheet1!J2/Sheet1!K2 -> 0.30168038 | J2: 400 | K2: =H62 -> 0.30939418
A3: 260 | B3: =A3+$E$2 -> 254 | C3: =Sheet1!B3/Sheet1!C3 -> 0.044872669 | D3: =C3*1.1 -> 0.049359936 | G3: 341 | H3: =Sheet1!J3/Sheet1!K3 -> 0.30343659 | J3: 401 | K3: =H63 -> 0.29746374
A4: 270 | B4: =A4+$E$2 -> 264 | C4: =Sheet1!B4/Sheet1!C4 -> 0.033178654 | D4: =C4*1.1 -> 0.03649652 | G4: 342 | H4: =Sheet1!J4/Sheet1!K4 -> 0.30327971 | J4: 402 | K4: =H64 -> 0.29218579
A5: 280 | B5: =A5+$E$2 -> 274 | C5: =Sheet1!B5/Sheet1!C5 -> 0.021507073 | D5: =C5*1.1 -> 0.02365778 | G5: 343 | H5: =Sheet1!J5/Sheet1!K5 -> 0.30439298 | J5: 403 | K5: =H65 -> 0.29092639
A6: 290 | B6: =A6+$E$2 -> 284 | C6: =Sheet1!B6/Sheet1!C6 -> 0.014545116 | D6: =C6*1.1 -> 0.015999627 | G6: 344 | H6: =Sheet1!J6/Sheet1!K6 -> 0.3040395 | J6: 404 | K6: =H66 -> 0.29412751
A7: 300 | B7: =A7+$E$2 -> 294 | C7: =Sheet1!B7/Sheet1!C7 -> 0.0098500954 | D7: =C7*1.1 -> 0.010835105 | G7: 345 | H7: =Sheet1!J7/Sheet1!K7 -> 0.30340784 | J7: 405 | K7: =H67 -> 0.30580636
A8: 310 | B8: =A8+$E$2 -> 304 | C8: =Sheet1!B8/Sheet1!C8 -> 0.0081794249 | D8: =C8*1.1 -> 0.0089973674 | G8: 346 | H8: =Sheet1!J8/Sheet1!K8 -> 0.30209171 | J8: 406 | K8: =H68 -> 0.32540984
A9: 320 | B9: =A9+$E$2 -> 314 | C9: =Sheet1!B9/Sheet1!C9 -> 0.0066788437 | D9: =C9*1.1 -> 0.0073467281 | G9: 347 | H9: =Sheet1!J9/Sheet1!K9 -> 0.30371911 | J9: 407 | K9: =H69 -> 0.35576987
A10: 330 | B10: =A10+$E$2 -> 324 | C10: =Sheet1!B10/Sheet1!C10 -> 0.0058479156 | D10: =C10*1.1 -> 0.0064327072 | G10: 348 | H10: =Sheet1!J10/Sheet1!K10 -> 0.30372364 | J10: 408 | K10: =H70 -> 0.39066561
A11: 340 | B11: =A11+$E$2 -> 334 | C11: =Sheet1!B11/Sheet1!C11 -> 0.0057528409 | D11: =C11*1.1 -> 0.006328125 | G11: 349 | H11: =Sheet1!J11/Sheet1!K11 -> 0.30555737 | J11: 409 | K11: =H71 -> 0.42087743
A12: 350 | B12: =A12+$E$2 -> 344 | C12: =Sheet1!B12/Sheet1!C12 -> 0.051483007 | D12: =C12*1.1 -> 0.056631308 | G12: 350 | H12: =Sheet1!J12/Sheet1!K12 -> 0.30601194 | J12: 410 | K12: =H72 -> 0.43902662
A13: 360 | B13: =A13+$E$2 -> 354 | C13: =Sheet1!B13/Sheet1!C13 -> 0.15925267 | D13: =C13*1.1 -> 0.17517794 | G13: 351 | H13: =Sheet1!J13/Sheet1!K13 -> 0.30434587 | J13: 411 | K13: =H73 -> 0.41612962
A14: 370 | B14: =A14+$E$2 -> 364 | C14: =Sheet1!B14/Sheet1!C14 -> 0.13736177 | D14: =C14*1.1 -> 0.15109795 | G14: 352 | H14: =Sheet1!J14/Sheet1!K14 -> 0.30477266 | J14: 412 | K14: =H74 -> 0.36567597
... A87: 1100 | B87: =A87+$E$2 -> 1094 | C87: =Sheet1!B87/Sheet1!C87 -> 0.2825441 | D87: =C87*1.1 -> 0.31079851 | G87: 425 | H87: =Sheet1!J87/Sheet1!K87 -> 0.36303743 | J87: 485 | K87: =H147 -> 0.5815671
G88: 426 | H88: =Sheet1!J88/Sheet1!K88 -> 0.43636091 | J88: 486 | K88: =H148 -> 0.6664594
G89: 427 | H89: =Sheet1!J89/Sheet1!K89 -> 0.5237713 | J89: 487 | K89: =H149 -> 0.72798664
G90: 428 | H90: =Sheet1!J90/Sheet1!K90 -> 0.60261407 | J90: 488 | K90: =H150 -> 0.74321755
G91: 429 | H91: =Sheet1!J91/Sheet1!K91 -> 0.65234947 | J91: 489 | K91: =H151 -> 0.70451613
G92: 430 | H92: =Sheet1!J92/Sheet1!K92 -> 0.64480988 | J92: 490 | K92: =H152 -> 0.6262212
G93: 431 | H93: =Sheet1!J93/Sheet1!K93 -> 0.58678846 | J93: 491 | K93: =H153 -> 0.53157368
G94: 432 | H94: =Sheet1!J94/Sheet1!K94 -> 0.50355739 | J94: 492 | K94: =H154 -> 0.44471829
G95: 433 | H95: =Sheet1!J95/Sheet1!K95 -> 0.43624543 | J95: 493 | K95: =H155 -> 0.37896988
G96: 434 | H96: =Sheet1!J96/Sheet1!K96 -> 0.39439872 | J96: 494 | K96: =H156 -> 0.33395488
G97: 435 | H97: =Sheet1!J97/Sheet1!K97 -> 0.37283929 | J97: 495 | K97: =H157 -> 0.30623963
G98: 436 | H98: =Sheet1!J98/Sheet1!K98 -> 0.36555954 | J98: 496 | K98: =H158 -> 0.29184785
G99: 437 | H99: =Sheet1!J99/Sheet1!K99 -> 0.3708715 | J99: 497 | K99: =H159 -> 0.28691137
... G583: 921 | H583: =Sheet1!J583/Sheet1!K583 -> 0.2931308 | J583: 981 | K583: =H643 -> 0.346577
G584: 922 | H584: =Sheet1!J584/Sheet1!K584 -> 0.29954099 | J584: 982 | K584: =FORECAST($G644, INDEX(D$2:D$87,MATCH($G644,$B$2:$B$87,1)):INDEX(D$2:D$87,MATCH($G644,$B$2:$B$87,1)+1), INDEX($B$2:$B$87,MATCH($G644,$B$2:$B$87,1)):INDEX($B$2:$B$87,MATCH($G644,$B$2:$B$87,1)+1)) -> 0.34490415
G585: 923 | H585: =Sheet1!J585/Sheet1!K585 -> 0.30611734 | J585: 983 | K585: =FORECAST($G645, INDEX(D$2:D$87,MATCH($G645,$B$2:$B$87,1)):INDEX(D$2:D$87,MATCH($G645,$B$2:$B$87,1)+1), INDEX($B$2:$B$87,MATCH($G645,$B$2:$B$87,1)):INDEX($B$2:$B$87,MATCH($G645,$B$2:$B$87,1)+1)) -> 0.3366588
G586: 924 | H586: =Sheet1!J586/Sheet1!K586 -> 0.31312212 | J586: 984 | K586: =FORECAST($G646, INDEX(D$2:D$87,MATCH($G646,$B$2:$B$87,1)):INDEX(D$2:D$87,MATCH($G646,$B$2:$B$87,1)+1), INDEX($B$2:$B$87,MATCH($G646,$B$2:$B$87,1)):INDEX($B$2:$B$87,MATCH($G646,$B$2:$B$87,1)+1)) -> 0.32841346
G587: 925 | H587: =Sheet1!J587/Sheet1!K587 -> 0.32127497 | J587: 985 | K587: =FORECAST($G647, INDEX(D$2:D$87,MATCH($G647,$B$2:$B$87,1)):INDEX(D$2:D$87,MATCH($G647,$B$2:$B$87,1)+1), INDEX($B$2:$B$87,MATCH($G647,$B$2:$B$87,1)):INDEX($B$2:$B$87,MATCH($G647,$B$2:$B$87,1)+1)) -> 0.32529529
G588: 926 | H588: =Sheet1!J588/Sheet1!K588 -> 0.32822523 | J588: 986 | K588: =FORECAST($G648, INDEX(D$2:D$87,MATCH($G648,$B$2:$B$87,1)):INDEX(D$2:D$87,MATCH($G648,$B$2:$B$87,1)+1), INDEX($B$2:$B$87,MATCH($G648,$B$2:$B$87,1)):INDEX($B$2:$B$87,MATCH($G648,$B$2:$B$87,1)+1)) -> 0.32217712
G589: 927 | H589: =Sheet1!J589/Sheet1!K589 -> 0.33572985 | J589: 987 | K589: =FORECAST($G649, INDEX(D$2:D$87,MATCH($G649,$B$2:$B$87,1)):INDEX(D$2:D$87,MATCH($G649,$B$2:$B$87,1)+1), INDEX($B$2:$B$87,MATCH($G649,$B$2:$B$87,1)):INDEX($B$2:$B$87,MATCH($G649,$B$2:$B$87,1)+1)) -> 0.31905895
G590: 928 | H590: =Sheet1!J590/Sheet1!K590 -> 0.34338399 | J590: 988 | K590: =FORECAST($G650, INDEX(D$2:D$87,MATCH($G650,$B$2:$B$87,1)):INDEX(D$2:D$87,MATCH($G650,$B$2:$B$87,1)+1), INDEX($B$2:$B$87,MATCH($G650,$B$2:$B$87,1)):INDEX($B$2:$B$87,MATCH($G650,$B$2:$B$87,1)+1)) -> 0.31594078
G591: 929 | H591: =Sheet1!J591/Sheet1!K591 -> 0.35099569 | J591: 989 | K591: =FORECAST($G651, INDEX(D$2:D$87,MATCH($G651,$B$2:$B$87,1)):INDEX(D$2:D$87,MATCH($G651,$B$2:$B$87,1)+1), INDEX($B$2:$B$87,MATCH($G651,$B$2:$B$87,1)):INDEX($B$2:$B$87,MATCH($G651,$B$2:$B$87,1)+1)) -> 0.31282261
G592: 930 | H592: =Sheet1!J592/Sheet1!K592 -> 0.36022863 | J592: 990 | K592: =FORECAST($G652, INDEX(D$2:D$87,MATCH($G652,$B$2:$B$87,1)):INDEX(D$2:D$87,MATCH($G652,$B$2:$B$87,1)+1), INDEX($B$2:$B$87,MATCH($G652,$B$2:$B$87,1)):INDEX($B$2:$B$87,MATCH($G652,$B$2:$B$87,1)+1)) -> 0.30970443
G593: 931 | H593: =Sheet1!J593/Sheet1!K593 -> 0.36802944 | J593: 991 | K593: =FORECAST($G653, INDEX(D$2:D$87,MATCH($G653,$B$2:$B$87,1)):INDEX(D$2:D$87,MATCH($G653,$B$2:$B$87,1)+1), INDEX($B$2:$B$87,MATCH($G653,$B$2:$B$87,1)):INDEX($B$2:$B$87,MATCH($G653,$B$2:$B$87,1)+1)) -> 0.30658626
G594: 932 | H594: =Sheet1!J594/Sheet1!K594 -> 0.37579128 | J594: 992 | K594: =FORECAST($G654, INDEX(D$2:D$87,MATCH($G654,$B$2:$B$87,1)):INDEX(D$2:D$87,MATCH($G654,$B$2:$B$87,1)+1), INDEX($B$2:$B$87,MATCH($G654,$B$2:$B$87,1)):INDEX($B$2:$B$87,MATCH($G654,$B$2:$B$87,1)+1)) -> 0.30346809
G595: 933 | H595: =Sheet1!J595/Sheet1!K595 -> 0.38574675 | J595: 993 | K595: =FORECAST($G655, INDEX(D$2:D$87,MATCH($G655,$B$2:$B$87,1)):INDEX(D$2:D$87,MATCH($G655,$B$2:$B$87,1)+1), INDEX($B$2:$B$87,MATCH($G655,$B$2:$B$87,1)):INDEX($B$2:$B$87,MATCH($G655,$B$2:$B$87,1)+1)) -> 0.30034992
...
